Traceback (most recent call last):
  File "/work/albertl_uri_edu/.conda/envs/sm/lib/python3.9/site-packages/urllib3/connectionpool.py", line 703, in urlopen
    httplib_response = self._make_request(
  File "/work/albertl_uri_edu/.conda/envs/sm/lib/python3.9/site-packages/urllib3/connectionpool.py", line 449, in _make_request
    six.raise_from(e, None)
  File "<string>", line 3, in raise_from
  File "/work/albertl_uri_edu/.conda/envs/sm/lib/python3.9/site-packages/urllib3/connectionpool.py", line 444, in _make_request
    httplib_response = conn.getresponse()
  File "/work/albertl_uri_edu/.conda/envs/sm/lib/python3.9/http/client.py", line 1377, in getresponse
    response.begin()
  File "/work/albertl_uri_edu/.conda/envs/sm/lib/python3.9/http/client.py", line 320, in begin
    version, status, reason = self._read_status()
  File "/work/albertl_uri_edu/.conda/envs/sm/lib/python3.9/http/client.py", line 289, in _read_status
    raise RemoteDisconnected("Remote end closed connection without"
http.client.RemoteDisconnected: Remote end closed connection without response

During handling of the above exception, another exception occurred:

Traceback (most recent call last):
  File "/work/albertl_uri_edu/.conda/envs/sm/lib/python3.9/site-packages/requests/adapters.py", line 440, in send
    resp = conn.urlopen(
  File "/work/albertl_uri_edu/.conda/envs/sm/lib/python3.9/site-packages/urllib3/connectionpool.py", line 785, in urlopen
    retries = retries.increment(
  File "/work/albertl_uri_edu/.conda/envs/sm/lib/python3.9/site-packages/urllib3/util/retry.py", line 550, in increment
    raise six.reraise(type(error), error, _stacktrace)
  File "/work/albertl_uri_edu/.conda/envs/sm/lib/python3.9/site-packages/urllib3/packages/six.py", line 769, in reraise
    raise value.with_traceback(tb)
  File "/work/albertl_uri_edu/.conda/envs/sm/lib/python3.9/site-packages/urllib3/connectionpool.py", line 703, in urlopen
    httplib_response = self._make_request(
  File "/work/albertl_uri_edu/.conda/envs/sm/lib/python3.9/site-packages/urllib3/connectionpool.py", line 449, in _make_request
    six.raise_from(e, None)
  File "<string>", line 3, in raise_from
  File "/work/albertl_uri_edu/.conda/envs/sm/lib/python3.9/site-packages/urllib3/connectionpool.py", line 444, in _make_request
    httplib_response = conn.getresponse()
  File "/work/albertl_uri_edu/.conda/envs/sm/lib/python3.9/http/client.py", line 1377, in getresponse
    response.begin()
  File "/work/albertl_uri_edu/.conda/envs/sm/lib/python3.9/http/client.py", line 320, in begin
    version, status, reason = self._read_status()
  File "/work/albertl_uri_edu/.conda/envs/sm/lib/python3.9/http/client.py", line 289, in _read_status
    raise RemoteDisconnected("Remote end closed connection without"
urllib3.exceptions.ProtocolError: ('Connection aborted.', RemoteDisconnected('Remote end closed connection without response'))

During handling of the above exception, another exception occurred:

Traceback (most recent call last):
  File "/work/albertl_uri_edu/mid_e/gl_dl_v22.py", line 97, in <module>
    response = session.get(i, stream=True)
  File "/work/albertl_uri_edu/.conda/envs/sm/lib/python3.9/site-packages/requests/sessions.py", line 542, in get
    return self.request('GET', url, **kwargs)
  File "/work/albertl_uri_edu/.conda/envs/sm/lib/python3.9/site-packages/requests/sessions.py", line 529, in request
    resp = self.send(prep, **send_kwargs)
  File "/work/albertl_uri_edu/.conda/envs/sm/lib/python3.9/site-packages/requests/sessions.py", line 645, in send
    r = adapter.send(request, **kwargs)
  File "/work/albertl_uri_edu/.conda/envs/sm/lib/python3.9/site-packages/requests/adapters.py", line 501, in send
    raise ConnectionError(err, request=request)
requests.exceptions.ConnectionError: ('Connection aborted.', RemoteDisconnected('Remote end closed connection without response'))
